<?xml version="1.0" encoding="utf-8"?>
<!-- This URDF was automatically created by SolidWorks to URDF Exporter! Originally created by Stephen Brawner (brawner@gmail.com) 
     Commit Version: 1.6.0-4-g7f85cfe  Build Version: 1.6.7995.38578
     For more information, please see http://wiki.ros.org/sw_urdf_exporter -->
<robot
  name="Legged_Robot">

  <mujoco>
        <compiler 
        meshdir="" 
        balanceinertia="true" 
        discardvisual="false" />
  </mujoco>




  <link
    name="base_link">
    <inertial>
      <origin
        xyz="0.003073 -1.1E-05 0.058211"
        rpy="0 0 0" />
      <mass
        value="5.276437" />
      <inertia
        ixx="0.032842099924"
        ixy="3.336928E-05"
        ixz="-0.007254554244"
        iyy="0.103762167556"
        iyz="3.335365E-05"
        izz="0.116538404566" />
    </inertial>
    <visual>
      <origin
        xyz="0 0 0"
        rpy="0 0 0" />
      <geometry>
        <mesh
          filename="package://狗V2.2.4.SLDASM/meshes/base_link.STL" />
      </geometry>
      <material
        name="">
        <color
          rgba="0.75294 0.75294 0.75294 1" />
      </material>
    </visual>
    <collision>
      <origin
        xyz="0 0 0"
        rpy="0 0 0" />
      <geometry>
        <mesh
          filename="package://狗V2.2.4.SLDASM/meshes/base_link.STL" />
      </geometry>
    </collision>
  </link>
  <link
    name="LF_HipA_link">
    <inertial>
      <origin
        xyz="0.002621 5.2E-05 0.046852"
        rpy="0 0 0" />
      <mass
        value="0.452382" />
      <inertia
        ixx="0.00055866874"
        ixy="3.41744E-07"
        ixz="-7.08495E-07"
        iyy="0.000347032635"
        iyz="-9.1476E-08"
        izz="0.000308951038" />
    </inertial>
    <visual>
      <origin
        xyz="0 0 0"
        rpy="0 0 0" />
      <geometry>
        <mesh
          filename="package://狗V2.2.4.SLDASM/meshes/LF_HipA_link.STL" />
      </geometry>
      <material
        name="">
        <color
          rgba="0.752941176470588 0.752941176470588 0.752941176470588 1" />
      </material>
    </visual>
    <collision>
      <origin
        xyz="0 0 0"
        rpy="0 0 0" />
      <geometry>
        <mesh
          filename="package://狗V2.2.4.SLDASM/meshes/LF_HipA_link.STL" />
      </geometry>
    </collision>
  </link>
  <joint
    name="LF_HipA_joint"
    type="revolute">
    <origin
      xyz="0.16 0.0674994572689366 0.0630000490222146"
      rpy="1.5707963267949 0 1.5707963267949" />
    <parent
      link="base_link" />
    <child
      link="LF_HipA_link" />
    <axis
      xyz="0 0 1" />
    <limit
      lower="-3.14"
      upper="3.14"
      effort="3"
      velocity="3" />
  </joint>
  <link
    name="LF_HipF_link">
    <inertial>
      <origin
        xyz="0.033261 -0.016881 0.050217"
        rpy="0 0 0" />
      <mass
        value="0.779164" />
      <inertia
        ixx="0.001597433226"
        ixy="0.001505087455"
        ixz="-0.000442930553"
        iyy="0.003268376129"
        iyz="0.000224661879"
        izz="0.004330433943" />
    </inertial>
    <visual>
      <origin
        xyz="0 0 0"
        rpy="0 0 0" />
      <geometry>
        <mesh
          filename="package://狗V2.2.4.SLDASM/meshes/LF_HipF_link.STL" />
      </geometry>
      <material
        name="">
        <color
          rgba="0.752941176470588 0.752941176470588 0.752941176470588 1" />
      </material>
    </visual>
    <collision>
      <origin
        xyz="0 0 0"
        rpy="0 0 0" />
      <geometry>
        <mesh
          filename="package://狗V2.2.4.SLDASM/meshes/LF_HipF_link.STL" />
      </geometry>
    </collision>
  </link>
  <joint
    name="LF_HipF_joint"
    type="revolute">
    <origin
      xyz="0.018001 0 0.048001"
      rpy="0 1.5708 0" />
    <parent
      link="LF_HipA_link" />
    <child
      link="LF_HipF_link" />
    <axis
      xyz="0 0 1" />
    <limit
      lower="-3.14"
      upper="3.14"
      effort="3"
      velocity="3" />
  </joint>
  <link
    name="LF_Knee_link">
    <inertial>
      <origin
        xyz="-0.055107 -0.080197 0.016515"
        rpy="0 0 0" />
      <mass
        value="0.121558" />
      <inertia
        ixx="0.000549292448"
        ixy="-0.000333360171"
        ixz="-1.07893E-07"
        iyy="0.000223695708"
        iyz="-1.88213E-07"
        izz="0.000769619177" />
    </inertial>
    <visual>
      <origin
        xyz="0 0 0"
        rpy="0 0 0" />
      <geometry>
        <mesh
          filename="package://狗V2.2.4.SLDASM/meshes/LF_Knee_link.STL" />
      </geometry>
      <material
        name="">
        <color
          rgba="1 1 1 1" />
      </material>
    </visual>
    <collision>
      <origin
        xyz="0 0 0"
        rpy="0 0 0" />
      <geometry>
        <mesh
          filename="package://狗V2.2.4.SLDASM/meshes/LF_Knee_link.STL" />
      </geometry>
    </collision>
  </link>
  <joint
    name="LF_Knee_joint"
    type="revolute">
    <origin
      xyz="0.170743431939306 -0.122257424197791 0.0500000000000068"
      rpy="0 0 0" />
    <parent
      link="LF_HipF_link" />
    <child
      link="LF_Knee_link" />
    <axis
      xyz="0 0 1" />
    <limit
      lower="-3.14"
      upper="3.14"
      effort="3"
      velocity="3" />
  </joint>
  <link
    name="LF_Foot_link">
    <inertial>
      <origin
        xyz="-0.000345 3.0E-06 -0.001836"
        rpy="0 0 0" />
      <mass
        value="0.038528" />
      <inertia
        ixx="8.433991E-06"
        ixy="-4.91E-10"
        ixz="2.2229E-07"
        iyy="7.946062E-06"
        iyz="-1.475E-09"
        izz="8.454215E-06" />
    </inertial>
    <visual>
      <origin
        xyz="0 0 0"
        rpy="0 0 0" />
      <geometry>
        <mesh
          filename="package://狗V2.2.4.SLDASM/meshes/LF_Foot_link.STL" />
      </geometry>
      <material
        name="">
        <color
          rgba="0.298039215686275 0.298039215686275 0.298039215686275 1" />
      </material>
    </visual>
    <collision>
      <origin
        xyz="0 0 0"
        rpy="0 0 0" />
      <geometry>
        <mesh
          filename="package://狗V2.2.4.SLDASM/meshes/LF_Foot_link.STL" />
      </geometry>
    </collision>
  </link>
  <joint
    name="LF_Foot_joint"
    type="fixed">
    <origin
      xyz="-0.110125305788291 -0.190742624824423 0.0164999999999972"
      rpy="1.5707963267949 0 3.14159265358979" />
    <parent
      link="LF_Knee_link" />
    <child
      link="LF_Foot_link" />
    <axis
      xyz="0 0 0" />
  </joint>
  <link
    name="LR_HipA_link">
    <inertial>
      <origin
        xyz="-0.002621 -5.2E-05 0.046852"
        rpy="0 0 0" />
      <mass
        value="0.452382" />
      <inertia
        ixx="0.00055866874"
        ixy="3.41744E-07"
        ixz="7.08495E-07"
        iyy="0.000347032635"
        iyz="9.1476E-08"
        izz="0.000308951038" />
    </inertial>
    <visual>
      <origin
        xyz="0 0 0"
        rpy="0 0 0" />
      <geometry>
        <mesh
          filename="package://狗V2.2.4.SLDASM/meshes/LR_HipA_link.STL" />
      </geometry>
      <material
        name="">
        <color
          rgba="0.752941176470588 0.752941176470588 0.752941176470588 1" />
      </material>
    </visual>
    <collision>
      <origin
        xyz="0 0 0"
        rpy="0 0 0" />
      <geometry>
        <mesh
          filename="package://狗V2.2.4.SLDASM/meshes/LR_HipA_link.STL" />
      </geometry>
    </collision>
  </link>
  <joint
    name="LR_HipA_joint"
    type="revolute">
    <origin
      xyz="-0.16 0.0674994572689466 0.0629999509777641"
      rpy="1.5707963267949 0 -1.5707963267949" />
    <parent
      link="base_link" />
    <child
      link="LR_HipA_link" />
    <axis
      xyz="0 0 1" />
    <limit
      lower="-3.14"
      upper="3.14"
      effort="3"
      velocity="3" />
  </joint>
  <link
    name="LR_HipF_link">
    <inertial>
      <origin
        xyz="0.03326 -0.016881 0.050217"
        rpy="0 0 0" />
      <mass
        value="0.779164" />
      <inertia
        ixx="0.001597433226"
        ixy="0.001505087455"
        ixz="-0.000442930553"
        iyy="0.003268376129"
        iyz="0.000224661879"
        izz="0.004330433943" />
    </inertial>
    <visual>
      <origin
        xyz="0 0 0"
        rpy="0 0 0" />
      <geometry>
        <mesh
          filename="package://狗V2.2.4.SLDASM/meshes/LR_HipF_link.STL" />
      </geometry>
      <material
        name="">
        <color
          rgba="0.752941176470588 0.752941176470588 0.752941176470588 1" />
      </material>
    </visual>
    <collision>
      <origin
        xyz="0 0 0"
        rpy="0 0 0" />
      <geometry>
        <mesh
          filename="package://狗V2.2.4.SLDASM/meshes/LR_HipF_link.STL" />
      </geometry>
    </collision>
  </link>
  <joint
    name="LR_HipF_joint"
    type="revolute">
    <origin
      xyz="-0.018001 0 0.048001"
      rpy="0 -1.5708 0" />
    <parent
      link="LR_HipA_link" />
    <child
      link="LR_HipF_link" />
    <axis
      xyz="0 0 1" />
    <limit
      lower="-3.14"
      upper="3.14"
      effort="3"
      velocity="3" />
  </joint>
  <link
    name="LR_Knee_link">
    <inertial>
      <origin
        xyz="-0.055107 -0.080197 0.016515"
        rpy="0 0 0" />
      <mass
        value="0.121558" />
      <inertia
        ixx="0.000549292448"
        ixy="-0.000333360171"
        ixz="-1.07893E-07"
        iyy="0.000223695708"
        iyz="-1.88213E-07"
        izz="0.000769619177" />
    </inertial>
    <visual>
      <origin
        xyz="0 0 0"
        rpy="0 0 0" />
      <geometry>
        <mesh
          filename="package://狗V2.2.4.SLDASM/meshes/LR_Knee_link.STL" />
      </geometry>
      <material
        name="">
        <color
          rgba="1 1 1 1" />
      </material>
    </visual>
    <collision>
      <origin
        xyz="0 0 0"
        rpy="0 0 0" />
      <geometry>
        <mesh
          filename="package://狗V2.2.4.SLDASM/meshes/LR_Knee_link.STL" />
      </geometry>
    </collision>
  </link>
  <joint
    name="LR_Knee_joint"
    type="revolute">
    <origin
      xyz="0.17074234647718 -0.122257326153361 0.050000000000001"
      rpy="0 0 0" />
    <parent
      link="LR_HipF_link" />
    <child
      link="LR_Knee_link" />
    <axis
      xyz="0 0 1" />
    <limit
      lower="-3.14"
      upper="3.14"
      effort="3"
      velocity="3" />
  </joint>
  <link
    name="LR_Foot_link">
    <inertial>
      <origin
        xyz="-0.000345 3.0E-06 -0.001836"
        rpy="0 0 0" />
      <mass
        value="0.038528" />
      <inertia
        ixx="8.433991E-06"
        ixy="-4.91E-10"
        ixz="2.2229E-07"
        iyy="7.946062E-06"
        iyz="-1.475E-09"
        izz="8.454215E-06" />
    </inertial>
    <visual>
      <origin
        xyz="0 0 0"
        rpy="0 0 0" />
      <geometry>
        <mesh
          filename="package://狗V2.2.4.SLDASM/meshes/LR_Foot_link.STL" />
      </geometry>
      <material
        name="">
        <color
          rgba="0.298039215686275 0.298039215686275 0.298039215686275 1" />
      </material>
    </visual>
    <collision>
      <origin
        xyz="0 0 0"
        rpy="0 0 0" />
      <geometry>
        <mesh
          filename="package://狗V2.2.4.SLDASM/meshes/LR_Foot_link.STL" />
      </geometry>
    </collision>
  </link>
  <joint
    name="LR_Foot_joint"
    type="fixed">
    <origin
      xyz="-0.110125305788291 -0.190742624824423 0.0164999999999997"
      rpy="1.5707963267949 0 -3.14159265358979" />
    <parent
      link="LR_Knee_link" />
    <child
      link="LR_Foot_link" />
    <axis
      xyz="0 0 0" />
  </joint>
  <link
    name="RF_HipA_link">
    <inertial>
      <origin
        xyz="-0.002621 -5.2E-05 0.046852"
        rpy="0 0 0" />
      <mass
        value="0.452382" />
      <inertia
        ixx="0.00055866874"
        ixy="3.41744E-07"
        ixz="7.08495E-07"
        iyy="0.000347032635"
        iyz="9.1476E-08"
        izz="0.000308951038" />
    </inertial>
    <visual>
      <origin
        xyz="0 0 0"
        rpy="0 0 0" />
      <geometry>
        <mesh
          filename="package://狗V2.2.4.SLDASM/meshes/RF_HipA_link.STL" />
      </geometry>
      <material
        name="">
        <color
          rgba="0.752941176470588 0.752941176470588 0.752941176470588 1" />
      </material>
    </visual>
    <collision>
      <origin
        xyz="0 0 0"
        rpy="0 0 0" />
      <geometry>
        <mesh
          filename="package://狗V2.2.4.SLDASM/meshes/RF_HipA_link.STL" />
      </geometry>
    </collision>
  </link>
  <joint
    name="RF_HipA_joint"
    type="revolute">
    <origin
      xyz="0.16 -0.0674994572689349 0.0629999509777826"
      rpy="1.5707963267949 0 1.5707963267949" />
    <parent
      link="base_link" />
    <child
      link="RF_HipA_link" />
    <axis
      xyz="0 0 1" />
    <limit
      lower="-3.14"
      upper="3.14"
      effort="3"
      velocity="3" />
  </joint>
  <link
    name="RF_HipF_link">
    <inertial>
      <origin
        xyz="-0.033247 -0.016939 0.050217"
        rpy="0 0 0" />
      <mass
        value="0.779164" />
      <inertia
        ixx="0.001595827327"
        ixy="-0.001503634909"
        ixz="0.000443182676"
        iyy="0.00326915934"
        iyz="0.000223603548"
        izz="0.004329611254" />
    </inertial>
    <visual>
      <origin
        xyz="0 0 0"
        rpy="0 0 0" />
      <geometry>
        <mesh
          filename="package://狗V2.2.4.SLDASM/meshes/RF_HipF_link.STL" />
      </geometry>
      <material
        name="">
        <color
          rgba="0.898039215686275 0.917647058823529 0.929411764705882 1" />
      </material>
    </visual>
    <collision>
      <origin
        xyz="0 0 0"
        rpy="0 0 0" />
      <geometry>
        <mesh
          filename="package://狗V2.2.4.SLDASM/meshes/RF_HipF_link.STL" />
      </geometry>
    </collision>
  </link>
  <joint
    name="RF_HipF_joint"
    type="revolute">
    <origin
      xyz="-0.018001 0 0.048001"
      rpy="0 -1.5708 0" />
    <parent
      link="RF_HipA_link" />
    <child
      link="RF_HipF_link" />
    <axis
      xyz="0 0 1" />
    <limit
      lower="-3.14"
      upper="3.14"
      effort="3"
      velocity="3" />
  </joint>
  <link
    name="RF_Knee_link">
    <inertial>
      <origin
        xyz="0.055107 -0.080197 0.016485"
        rpy="0 0 0" />
      <mass
        value="0.121558" />
      <inertia
        ixx="0.000549292448"
        ixy="0.000333360171"
        ixz="-1.07893E-07"
        iyy="0.000223695708"
        iyz="1.88213E-07"
        izz="0.000769619177" />
    </inertial>
    <visual>
      <origin
        xyz="0 0 0"
        rpy="0 0 0" />
      <geometry>
        <mesh
          filename="package://狗V2.2.4.SLDASM/meshes/RF_Knee_link.STL" />
      </geometry>
      <material
        name="">
        <color
          rgba="1 1 1 1" />
      </material>
    </visual>
    <collision>
      <origin
        xyz="0 0 0"
        rpy="0 0 0" />
      <geometry>
        <mesh
          filename="package://狗V2.2.4.SLDASM/meshes/RF_Knee_link.STL" />
      </geometry>
    </collision>
  </link>
  <joint
    name="RF_Knee_joint"
    type="revolute">
    <origin
      xyz="-0.17074 -0.12226 0.05"
      rpy="0 0 0" />
    <parent
      link="RF_HipF_link" />
    <child
      link="RF_Knee_link" />
    <axis
      xyz="0 0 1" />
    <limit
      lower="-3.14"
      upper="3.14"
      effort="3"
      velocity="3" />
  </joint>
  <link
    name="RF_Foot_link">
    <inertial>
      <origin
        xyz="-0.000345 3.0E-06 -0.001836"
        rpy="0 0 0" />
      <mass
        value="0.038528" />
      <inertia
        ixx="8.433991E-06"
        ixy="-4.91E-10"
        ixz="2.2229E-07"
        iyy="7.946062E-06"
        iyz="-1.475E-09"
        izz="8.454215E-06" />
    </inertial>
    <visual>
      <origin
        xyz="0 0 0"
        rpy="0 0 0" />
      <geometry>
        <mesh
          filename="package://狗V2.2.4.SLDASM/meshes/RF_Foot_link.STL" />
      </geometry>
      <material
        name="">
        <color
          rgba="0.298039215686275 0.298039215686275 0.298039215686275 1" />
      </material>
    </visual>
    <collision>
      <origin
        xyz="0 0 0"
        rpy="0 0 0" />
      <geometry>
        <mesh
          filename="package://狗V2.2.4.SLDASM/meshes/RF_Foot_link.STL" />
      </geometry>
    </collision>
  </link>
  <joint
    name="RF_Foot_joint"
    type="fixed">
    <origin
      xyz="0.110125305788291 -0.190742624824423 0.0165000000000002"
      rpy="-1.5707963267949 0 0" />
    <parent
      link="RF_Knee_link" />
    <child
      link="RF_Foot_link" />
    <axis
      xyz="0 0 0" />
  </joint>
  <link
    name="RR_HipA_link">
    <inertial>
      <origin
        xyz="0.002621 5.2E-05 0.046852"
        rpy="0 0 0" />
      <mass
        value="0.452382" />
      <inertia
        ixx="0.00055866874"
        ixy="3.41744E-07"
        ixz="-7.08495E-07"
        iyy="0.000347032635"
        iyz="-9.1476E-08"
        izz="0.000308951038" />
    </inertial>
    <visual>
      <origin
        xyz="0 0 0"
        rpy="0 0 0" />
      <geometry>
        <mesh
          filename="package://狗V2.2.4.SLDASM/meshes/RR_HipA_link.STL" />
      </geometry>
      <material
        name="">
        <color
          rgba="1 1 1 1" />
      </material>
    </visual>
    <collision>
      <origin
        xyz="0 0 0"
        rpy="0 0 0" />
      <geometry>
        <mesh
          filename="package://狗V2.2.4.SLDASM/meshes/RR_HipA_link.STL" />
      </geometry>
    </collision>
  </link>
  <joint
    name="RR_HipA_joint"
    type="revolute">
    <origin
      xyz="-0.16 -0.0674994572689364 0.0630000490222165"
      rpy="1.5707963267949 0 -1.5707963267949" />
    <parent
      link="base_link" />
    <child
      link="RR_HipA_link" />
    <axis
      xyz="0 0 1" />
    <limit
      lower="-3.14"
      upper="3.14"
      effort="3"
      velocity="3" />
  </joint>
  <link
    name="RR_HipF_link">
    <inertial>
      <origin
        xyz="-0.033246 -0.01694 0.050217"
        rpy="0 0 0" />
      <mass
        value="0.779164" />
      <inertia
        ixx="0.001595827327"
        ixy="-0.001503634909"
        ixz="0.000443182676"
        iyy="0.00326915934"
        iyz="0.000223603548"
        izz="0.004329611254" />
    </inertial>
    <visual>
      <origin
        xyz="0 0 0"
        rpy="0 0 0" />
      <geometry>
        <mesh
          filename="package://狗V2.2.4.SLDASM/meshes/RR_HipF_link.STL" />
      </geometry>
      <material
        name="">
        <color
          rgba="0.752941176470588 0.752941176470588 0.752941176470588 1" />
      </material>
    </visual>
    <collision>
      <origin
        xyz="0 0 0"
        rpy="0 0 0" />
      <geometry>
        <mesh
          filename="package://狗V2.2.4.SLDASM/meshes/RR_HipF_link.STL" />
      </geometry>
    </collision>
  </link>
  <joint
    name="RR_HipF_joint"
    type="revolute">
    <origin
      xyz="0.018001 0 0.048001"
      rpy="0 1.5708 0" />
    <parent
      link="RR_HipA_link" />
    <child
      link="RR_HipF_link" />
    <axis
      xyz="0 0 1" />
    <limit
      lower="-3.14"
      upper="3.14"
      effort="3"
      velocity="3" />
  </joint>
  <link
    name="RR_Knee_link">
    <inertial>
      <origin
        xyz="0.055107 -0.080197 0.016485"
        rpy="0 0 0" />
      <mass
        value="0.121558" />
      <inertia
        ixx="0.000549292448"
        ixy="0.000333360171"
        ixz="-1.07893E-07"
        iyy="0.000223695708"
        iyz="1.88213E-07"
        izz="0.000769619177" />
    </inertial>
    <visual>
      <origin
        xyz="0 0 0"
        rpy="0 0 0" />
      <geometry>
        <mesh
          filename="package://狗V2.2.4.SLDASM/meshes/RR_Knee_link.STL" />
      </geometry>
      <material
        name="">
        <color
          rgba="1 1 1 1" />
      </material>
    </visual>
    <collision>
      <origin
        xyz="0 0 0"
        rpy="0 0 0" />
      <geometry>
        <mesh
          filename="package://狗V2.2.4.SLDASM/meshes/RR_Knee_link.STL" />
      </geometry>
    </collision>
  </link>
  <joint
    name="RR_Knee_joint"
    type="revolute">
    <origin
      xyz="-0.170742346477182 -0.122257424197793 0.050000000000007"
      rpy="0 0 0" />
    <parent
      link="RR_HipF_link" />
    <child
      link="RR_Knee_link" />
    <axis
      xyz="0 0 1" />
    <limit
      lower="-3.14"
      upper="3.14"
      effort="3"
      velocity="3" />
  </joint>
  <link
    name="RR_Foot_link">
    <inertial>
      <origin
        xyz="-0.000345 3.0E-06 -0.001836"
        rpy="0 0 0" />
      <mass
        value="0.038528" />
      <inertia
        ixx="8.433991E-06"
        ixy="-4.91E-10"
        ixz="2.2229E-07"
        iyy="7.946062E-06"
        iyz="-1.475E-09"
        izz="8.454215E-06" />
    </inertial>
    <visual>
      <origin
        xyz="0 0 0"
        rpy="0 0 0" />
      <geometry>
        <mesh
          filename="package://狗V2.2.4.SLDASM/meshes/RR_Foot_link.STL" />
      </geometry>
      <material
        name="">
        <color
          rgba="0.29804 0.29804 0.29804 1" />
      </material>
    </visual>
    <collision>
      <origin
        xyz="0 0 0"
        rpy="0 0 0" />
      <geometry>
        <mesh
          filename="package://狗V2.2.4.SLDASM/meshes/RR_Foot_link.STL" />
      </geometry>
    </collision>
  </link>
  <joint
    name="RR_Foot_joint"
    type="fixed">
    <origin
      xyz="0.11013 -0.19074 0.0165"
      rpy="-1.5708 0 0" />
    <parent
      link="RR_Knee_link" />
    <child
      link="RR_Foot_link" />
    <axis
      xyz="0 0 0" />
  </joint>
</robot>